Workbook

Sheet Raw_Data
A1: Respondent_ID | B1: Age | C1: Gender | D1: City | E1: Occupation | F1: Monthly_Income | G1: Awareness_Digital_Gold | H1: Platform_Used | I1: Frequency_of_Purchase | J1: Investment_Amount_INR | K1: Purpose_of_Buying | L1: Trust_Level | M1: Risk_Perception | N1: Preferred_Investment_Type | O1: Satisfaction_Level | P1: Recommendation_Likelihood
A2: R001 | B2: 25 | C2: Female | D2: Chennai | E2: Student | F2: 20,000-40,000 | G2: Yes | H2: PhonePe | I2: Quarterly | J2: 1597 | K2: Savings | L2: 4 | M2: Medium | N2: Fixed Deposit | O2: 1 | P2: 8
A3: R002 | B3: 60 | C3: Male | D3: Mumbai | E3: Homemaker | G3: Yes | H3: Zerodha | I3: Weekly | J3: 389 | K3: Investment | L3: 5 | M3: Medium | N3: Digital Gold | O3: 2 | P3: 5
A4: R003 | B4: 41 | C4: Female | D4: Bangalore | E4: Salaried | F4: Below 20,000 | G4: Yes | H4: Paytm | I4: Daily | J4: 568 | K4: Savings | L4: 4 | M4: Low | N4: Digital Gold | O4: 5 | P4: 1
A5: R004 | B5: 52 | C5: Male | D5: Lucknow | E5: Government Employee | F5: 60,000-80,000 | G5: Yes | H5: Paytm | I5: Quarterly | J5: 7896 | K5: Investment | L5: 4 | M5: High | N5: Digital Gold | O5: 5 | P5: 10
A6: R005 | B6: 51 | C6: Female | D6: Kolkata | E6: Business | F6: 40,000-60,000 | G6: No | L6: 2 | M6: High | N6: Digital Gold | O6: 5 | P6: 3
A7: R006 | B7: 36 | C7: Male | D7: Delhi | E7: Freelancer | F7: Below 20,000 | G7: No | L7: 1 | M7: High | N7: Digital Gold | O7: 2 | P7: 9
A8: R007 | B8: 21 | C8: Female | D8: Delhi | E8: Government Employee | F8: Below 20,000 | G8: Yes | H8: Others | I8: Quarterly | J8: 266 | K8: Investment | L8: 2 | M8: Medium | N8: Fixed Deposit | O8: 1 | P8: 7
A9: R008 | B9: 59 | C9: Male | D9: Kolkata | E9: Business | F9: Above 80,000 | G9: No | L9: 1 | M9: Low | N9: Digital Gold | O9: 3 | P9: 7
A10: R009 | B10: 18 | C10: Female | D10: Lucknow | E10: Government Employee | G10: Yes | H10: Zerodha | I10: Rarely | J10: 821 | K10: Savings | L10: 5 | M10: Low | N10: Fixed Deposit | O10: 3 | P10: 7
A11: R010 | B11: 38 | C11: Male | D11: Jaipur | E11: Student | F11: Below 20,000 | G11: Yes | H11: Google Pay | I11: Rarely | J11: 256 | K11: Savings | L11: 1 | M11: High | N11: Digital Gold | O11: 1 | P11: 2
A12: R011 | B12: 22 | C12: Female | D12: Ahmedabad | E12: Freelancer | F12: Above 80,000 | G12: Yes | H12: MMTC-PAMP | I12: Quarterly | J12: 13020 | K12: Savings | L12: 2 | M12: High | N12: Digital Gold | O12: 5 | P12: 8
A13: R012 | B13: 36 | C13: Female | D13: Kolkata | E13: Freelancer | F13: Above 80,000 | G13: Yes | H13: Groww | I13: Monthly | J13: 25253 | K13: Gifting | M13: High | N13: Mutual Funds | O13: 4 | P13: 5
A14: R013 | B14: 34 | C14: Female | D14: Mumbai | E14: Freelancer | F14: Below 20,000 | G14: Yes | H14: Paytm | I14: Quarterly | J14: 414 | K14: Investment | L14: 5 | M14: Low | N14: Mutual Funds | O14: 5 | P14: 10
A15: R014 | B15: 57 | C15: Female | D15: Ahmedabad | E15: Student | F15: 20,000-40,000 | G15: No | L15: 2 | M15: Low | N15: Mutual Funds | O15: 1 | P15: 5
A16: R015 | B16: 30 | D16: Ahmedabad | E16: Government Employee | F16: Above 80,000 | G16: Yes | H16: Others | I16: Quarterly | J16: 26493 | K16: Investment | L16: 1 | M16: Low | N16: Mutual Funds | O16: 5 | P16: 3
A17: R016 | B17: 22 | C17: Male | D17: Mumbai | E17: Homemaker | F17: Below 20,000 | G17: No | L17: 1 | M17: Medium | N17: Digital Gold | O17: 3 | P17: 3
A18: R017 | B18: 44 | C18: Female | D18: Mumbai | E18: Business | F18: Below 20,000 | G18: No | L18: 1 | M18: High | N18: Digital Gold | O18: 5 | P18: 1
A19: R018 | B19: 22 | C19: Female | D19: Mumbai | E19: Salaried | F19: Below 20,000 | G19: No | L19: 2 | M19: Low | N19: Digital Gold | O19: 2 | P19: 2
A20: R019 | B20: 60 | C20: Female | D20: Hyderabad | E20: Homemaker | G20: No | L20: 1 | M20: High | N20: Fixed Deposit | O20: 3 | P20: 1
A21: R020 | B21: 37 | C21: Male | D21: Chennai | E21: Freelancer | F21: Below 20,000 | G21: Yes | H21: PhonePe | I21: Monthly | J21: 879 | K21: Savings | L21: 2 | M21: Low | N21: Fixed Deposit | O21: 2 | P21: 8
A22: R021 | B22: 57 | C22: Female | D22: Delhi | E22: Government Employee | F22: 40,000-60,000 | G22: No | L22: 3 | M22: Low | N22: Digital Gold | O22: 3 | P22: 3
A23: R022 | B23: 26 | C23: Male | D23: Chennai | E23: Student | F23: 60,000-80,000 | G23: No | L23: 1 | M23: Medium | N23: Fixed Deposit | O23: 1 | P23: 2
A24: R023 | B24: 44 | C24: Female | D24: Delhi | E24: Freelancer | F24: Above 80,000 | G24: Yes | H24: PhonePe | I24: Daily | J24: 20744 | K24: Investment | L24: 5 | M24: Medium | N24: Physical Gold | O24: 5 | P24: 10
A25: R024 | B25: 44 | C25: Male | D25: Ahmedabad | E25: Salaried | F25: 40,000-60,000 | G25: No | L25: 1 | M25: Low | N25: Digital Gold | O25: 3 | P25: 4
A26: R025 | B26: 37 | C26: Male | D26: Lucknow | E26: Student | G26: Yes | H26: Groww | I26: Quarterly | J26: 29429 | K26: Savings | L26: 1 | M26: High | N26: Digital Gold | O26: 2 | P26: 2
A27: R026 | B27: 27 | C27: Female | D27: Jaipur | E27: Government Employee | F27: Below 20,000 | G27: Yes | H27: PhonePe | I27: Quarterly | J27: 775 | K27: Investment | L27: 3 | M27: Medium | N27: Physical Gold | O27: 1 | P27: 7
A28: R027 | B28: 51 | C28: Male | D28: Chennai | E28: Government Employee | F28: 20,000-40,000 | G28: Yes | H28: MMTC-PAMP | I28: Quarterly | J28: 2902 | K28: Investment | L28: 3 | M28: Low | N28: Fixed Deposit | O28: 5 | P28: 6
A29: R028 | B29: 44 | C29: Male | D29: Lucknow | E29: Freelancer | F29: Above 80,000 | G29: Yes | H29: MMTC-PAMP | I29: Daily | J29: 25559 | K29: Investment | L29: 3 | M29: High | N29: Digital Gold | O29: 5 | P29: 4
A30: R029 | B30: 45 | C30: Female | D30: Chennai | E30: Student | F30: Above 80,000 | G30: Yes | H30: MMTC-PAMP | I30: Quarterly | J30: 15486 | K30: Investment | L30: 4 | M30: Low | N30: Mutual Funds | O30: 2 | P30: 10
A31: R030 | B31: 34 | C31: Female | D31: Kolkata | E31: Government Employee | F31: 20,000-40,000 | G31: Yes | H31: Paytm | I31: Monthly | J31: 2680 | K31: Savings | L31: 3 | M31: Medium | N31: Physical Gold | O31: 4 | P31: 7
A32: R031 | B32: 32 | C32: Male | D32: Hyderabad | E32: Salaried | F32: 40,000-60,000 | G32: No | L32: 3 | M32: Medium | N32: Digital Gold | O32: 3 | P32: 4
A33: R032 | B33: 39 | C33: Male | D33: Delhi | E33: Homemaker | F33: 60,000-80,000 | G33: Yes | H33: PhonePe | I33: Monthly | J33: 10978 | K33: Savings | L33: 1 | M33: Low | N33: Digital Gold | O33: 5 | P33: 2
A34: R033 | B34: 18 | C34: Male | D34: Chennai | E34: Freelancer | F34: 20,000-40,000 | G34: Yes | H34: PhonePe | I34: Rarely | J34: 2868 | K34: Gifting | L34: 2 | M34: Medium | N34: Physical Gold | O34: 3 | P34: 2
A35: R034 | B35: 18 | C35: Male | D35: Kolkata | E35: Freelancer | F35: Above 80,000 | G35: Yes | H35: Paytm | I35: Daily | J35: 21120 | K35: Investment | L35: 2 | M35: Medium | N35: Digital Gold | O35: 3 | P35: 9
A36: R035 | B36: 59 | C36: Male | D36: Jaipur | E36: Salaried | F36: Below 20,000 | G36: Yes | H36: Groww | I36: Daily | J36: 820 | K36: Savings | L36: 1 | M36: Low | N36: Digital Gold | O36: 5 | P36: 5
A37: R036 | B37: 27 | C37: Male | D37: Delhi | E37: Student | F37: 20,000-40,000 | G37: No | L37: 2 | M37: Medium | N37: Digital Gold | O37: 4 | P37: 3
A38: R037 | B38: 50 | C38: Male | D38: Mumbai | E38: Homemaker | F38: 60,000-80,000 | G38: No | L38: 2 | M38: Low | N38: Digital Gold | O38: 4 | P38: 8
A39: R038 | B39: 22 | D39: Hyderabad | E39: Freelancer | F39: 60,000-80,000 | G39: Yes | H39: PhonePe | I39: Rarely | J39: 12726 | K39: Investment | L39: 4 | M39: High | N39: Physical Gold | O39: 5 | P39: 1
A40: R039 | B40: 41 | D40: Mumbai | E40: Student | G40: Yes | H40: Zerodha | I40: Weekly | J40: 626 | K40: Savings | L40: 3 | M40: Low | N40: Digital Gold | O40: 1 | P40: 4
...

Sheet Cleaned_Data
A1: Respondent_ID | B1: Age | C1: Gender | D1: City | E1: Occupation | F1: Monthly_Income | G1: Awareness_Digital_Gold | H1: Platform_Used | I1: Frequency_of_Purchase | J1: Investment_Amount_INR | K1: Purpose_of_Buying | L1: Trust_Level | M1: Risk_Perception | N1: Preferred_Investment_Type | O1: Satisfaction_Level | P1: Recommendation_Likelihood | Q1: Age_Group | R1: Income_Numeric | S1: Aware_Flag
A2: =Raw_Data!A2 -> R001 | B2: =Raw_Data!B2 -> 25 | C2: =Raw_Data!C2 -> Female | D2: =Raw_Data!D2 -> Chennai | E2: =Raw_Data!E2 -> Student | F2: =Raw_Data!F2 -> 20,000-40,000 | G2: =Raw_Data!G2 -> Yes | H2: =Raw_Data!H2 -> PhonePe | ... P2: =Raw_Data!P2 -> 8 | Q2: =IF(OR(B2="",B2=0),"Unknown",IF(B2<=25,"18-25",IF(B2<=35,"26-35",IF(B2<=45,"36-45","46+")))) -> 18-25 | R2: =IF(F2="Below 20,000",10000,IF(F2="20,000-40,000",30000,IF(F2="40,000-60,000",50000,IF(F2="60,000-80,000",70000,IF(F2="Above 80,000",100000,0))))) -> 30000 | S2: =IF(G2="Yes",1,0) -> 1
A3: =Raw_Data!A3 -> R002 | B3: =Raw_Data!B3 -> 60 | C3: =Raw_Data!C3 -> Male | D3: =Raw_Data!D3 -> Mumbai | E3: =Raw_Data!E3 -> Homemaker | F3: =Raw_Data!F3 -> 0 | G3: =Raw_Data!G3 -> Yes | H3: =Raw_Data!H3 -> Zerodha | ... P3: =Raw_Data!P3 -> 5 | Q3: =IF(OR(B3="",B3=0),"Unknown",IF(B3<=25,"18-25",IF(B3<=35,"26-35",IF(B3<=45,"36-45","46+")))) -> 46+ | R3: =IF(F3="Below 20,000",10000,IF(F3="20,000-40,000",30000,IF(F3="40,000-60,000",50000,IF(F3="60,000-80,000",70000,IF(F3="Above 80,000",100000,0))))) -> 0 | S3: =IF(G3="Yes",1,0) -> 1
A4: =Raw_Data!A4 -> R003 | B4: =Raw_Data!B4 -> 41 | C4: =Raw_Data!C4 -> Female | D4: =Raw_Data!D4 -> Bangalore | E4: =Raw_Data!E4 -> Salaried | F4: =Raw_Data!F4 -> Below 20,000 | G4: =Raw_Data!G4 -> Yes | H4: =Raw_Data!H4 -> Paytm | ... P4: =Raw_Data!P4 -> 1 | Q4: =IF(OR(B4="",B4=0),"Unknown",IF(B4<=25,"18-25",IF(B4<=35,"26-35",IF(B4<=45,"36-45","46+")))) -> 36-45 | R4: =IF(F4="Below 20,000",10000,IF(F4="20,000-40,000",30000,IF(F4="40,000-60,000",50000,IF(F4="60,000-80,000",70000,IF(F4="Above 80,000",100000,0))))) -> 10000 | S4: =IF(G4="Yes",1,0) -> 1
A5: =Raw_Data!A5 -> R004 | B5: =Raw_Data!B5 -> 52 | C5: =Raw_Data!C5 -> Male | D5: =Raw_Data!D5 -> Lucknow | E5: =Raw_Data!E5 -> Government Employee | F5: =Raw_Data!F5 -> 60,000-80,000 | G5: =Raw_Data!G5 -> Yes | H5: =Raw_Data!H5 -> Paytm | ... P5: =Raw_Data!P5 -> 10 | Q5: =IF(OR(B5="",B5=0),"Unknown",IF(B5<=25,"18-25",IF(B5<=35,"26-35",IF(B5<=45,"36-45","46+")))) -> 46+ | R5: =IF(F5="Below 20,000",10000,IF(F5="20,000-40,000",30000,IF(F5="40,000-60,000",50000,IF(F5="60,000-80,000",70000,IF(F5="Above 80,000",100000,0))))) -> 70000 | S5: =IF(G5="Yes",1,0) -> 1
A6: =Raw_Data!A6 -> R005 | B6: =Raw_Data!B6 -> 51 | C6: =Raw_Data!C6 -> Female | D6: =Raw_Data!D6 -> Kolkata | E6: =Raw_Data!E6 -> Business | F6: =Raw_Data!F6 -> 40,000-60,000 | G6: =Raw_Data!G6 -> No | H6: =Raw_Data!H6 -> 0 | ... P6: =Raw_Data!P6 -> 3 | Q6: =IF(OR(B6="",B6=0),"Unknown",IF(B6<=25,"18-25",IF(B6<=35,"26-35",IF(B6<=45,"36-45","46+")))) -> 46+ | R6: =IF(F6="Below 20,000",10000,IF(F6="20,000-40,000",30000,IF(F6="40,000-60,000",50000,IF(F6="60,000-80,000",70000,IF(F6="Above 80,000",100000,0))))) -> 50000 | S6: =IF(G6="Yes",1,0) -> 0
A7: =Raw_Data!A7 -> R006 | B7: =Raw_Data!B7 -> 36 | C7: =Raw_Data!C7 -> Male | D7: =Raw_Data!D7 -> Delhi | E7: =Raw_Data!E7 -> Freelancer | F7: =Raw_Data!F7 -> Below 20,000 | G7: =Raw_Data!G7 -> No | H7: =Raw_Data!H7 -> 0 | ... P7: =Raw_Data!P7 -> 9 | Q7: =IF(OR(B7="",B7=0),"Unknown",IF(B7<=25,"18-25",IF(B7<=35,"26-35",IF(B7<=45,"36-45","46+")))) -> 36-45 | R7: =IF(F7="Below 20,000",10000,IF(F7="20,000-40,000",30000,IF(F7="40,000-60,000",50000,IF(F7="60,000-80,000",70000,IF(F7="Above 80,000",100000,0))))) -> 10000 | S7: =IF(G7="Yes",1,0) -> 0
A8: =Raw_Data!A8 -> R007 | B8: =Raw_Data!B8 -> 21 | C8: =Raw_Data!C8 -> Female | D8: =Raw_Data!D8 -> Delhi | E8: =Raw_Data!E8 -> Government Employee | F8: =Raw_Data!F8 -> Below 20,000 | G8: =Raw_Data!G8 -> Yes | H8: =Raw_Data!H8 -> Others | ... P8: =Raw_Data!P8 -> 7 | Q8: =IF(OR(B8="",B8=0),"Unknown",IF(B8<=25,"18-25",IF(B8<=35,"26-35",IF(B8<=45,"36-45","46+")))) -> 18-25 | R8: =IF(F8="Below 20,000",10000,IF(F8="20,000-40,000",30000,IF(F8="40,000-60,000",50000,IF(F8="60,000-80,000",70000,IF(F8="Above 80,000",100000,0))))) -> 10000 | S8: =IF(G8="Yes",1,0) -> 1
A9: =Raw_Data!A9 -> R008 | B9: =Raw_Data!B9 -> 59 | C9: =Raw_Data!C9 -> Male | D9: =Raw_Data!D9 -> Kolkata | E9: =Raw_Data!E9 -> Business | F9: =Raw_Data!F9 -> Above 80,000 | G9: =Raw_Data!G9 -> No | H9: =Raw_Data!H9 -> 0 | ... P9: =Raw_Data!P9 -> 7 | Q9: =IF(OR(B9="",B9=0),"Unknown",IF(B9<=25,"18-25",IF(B9<=35,"26-35",IF(B9<=45,"36-45","46+")))) -> 46+ | R9: =IF(F9="Below 20,000",10000,IF(F9="20,000-40,000",30000,IF(F9="40,000-60,000",50000,IF(F9="60,000-80,000",70000,IF(F9="Above 80,000",100000,0))))) -> 100000 | S9: =IF(G9="Yes",1,0) -> 0
A10: =Raw_Data!A10 -> R009 | B10: =Raw_Data!B10 -> 18 | C10: =Raw_Data!C10 -> Female | D10: =Raw_Data!D10 -> Lucknow | E10: =Raw_Data!E10 -> Government Employee | F10: =Raw_Data!F10 -> 0 | G10: =Raw_Data!G10 -> Yes | H10: =Raw_Data!H10 -> Zerodha | ... P10: =Raw_Data!P10 -> 7 | Q10: =IF(OR(B10="",B10=0),"Unknown",IF(B10<=25,"18-25",IF(B10<=35,"26-35",IF(B10<=45,"36-45","46+")))) -> 18-25 | R10: =IF(F10="Below 20,000",10000,IF(F10="20,000-40,000",30000,IF(F10="40,000-60,000",50000,IF(F10="60,000-80,000",70000,IF(F10="Above 80,000",100000,0))))) -> 0 | S10: =IF(G10="Yes",1,0) -> 1
A11: =Raw_Data!A11 -> R010 | B11: =Raw_Data!B11 -> 38 | C11: =Raw_Data!C11 -> Male | D11: =Raw_Data!D11 -> Jaipur | E11: =Raw_Data!E11 -> Student | F11: =Raw_Data!F11 -> Below 20,000 | G11: =Raw_Data!G11 -> Yes | H11: =Raw_Data!H11 -> Google Pay | ... P11: =Raw_Data!P11 -> 2 | Q11: =IF(OR(B11="",B11=0),"Unknown",IF(B11<=25,"18-25",IF(B11<=35,"26-35",IF(B11<=45,"36-45","46+")))) -> 36-45 | R11: =IF(F11="Below 20,000",10000,IF(F11="20,000-40,000",30000,IF(F11="40,000-60,000",50000,IF(F11="60,000-80,000",70000,IF(F11="Above 80,000",100000,0))))) -> 10000 | S11: =IF(G11="Yes",1,0) -> 1
A12: =Raw_Data!A12 -> R011 | B12: =Raw_Data!B12 -> 22 | C12: =Raw_Data!C12 -> Female | D12: =Raw_Data!D12 -> Ahmedabad | E12: =Raw_Data!E12 -> Freelancer | F12: =Raw_Data!F12 -> Above 80,000 | G12: =Raw_Data!G12 -> Yes | H12: =Raw_Data!H12 -> MMTC-PAMP | ... P12: =Raw_Data!P12 -> 8 | Q12: =IF(OR(B12="",B12=0),"Unknown",IF(B12<=25,"18-25",IF(B12<=35,"26-35",IF(B12<=45,"36-45","46+")))) -> 18-25 | R12: =IF(F12="Below 20,000",10000,IF(F12="20,000-40,000",30000,IF(F12="40,000-60,000",50000,IF(F12="60,000-80,000",70000,IF(F12="Above 80,000",100000,0))))) -> 100000 | S12: =IF(G12="Yes",1,0) -> 1
A13: =Raw_Data!A13 -> R012 | B13: =Raw_Data!B13 -> 36 | C13: =Raw_Data!C13 -> Female | D13: =Raw_Data!D13 -> Kolkata | E13: =Raw_Data!E13 -> Freelancer | F13: =Raw_Data!F13 -> Above 80,000 | G13: =Raw_Data!G13 -> Yes | H13: =Raw_Data!H13 -> Groww | ... P13: =Raw_Data!P13 -> 5 | Q13: =IF(OR(B13="",B13=0),"Unknown",IF(B13<=25,"18-25",IF(B13<=35,"26-35",IF(B13<=45,"36-45","46+")))) -> 36-45 | R13: =IF(F13="Below 20,000",10000,IF(F13="20,000-40,000",30000,IF(F13="40,000-60,000",50000,IF(F13="60,000-80,000",70000,IF(F13="Above 80,000",100000,0))))) -> 100000 | S13: =IF(G13="Yes",1,0) -> 1
... A304: =Raw_Data!A304 -> R303 | B304: =Raw_Data!B304 -> 45 | C304: =Raw_Data!C304 -> Female | D304: =Raw_Data!D304 -> Delhi | E304: =Raw_Data!E304 -> Government Employee | F304: =Raw_Data!F304 -> 20,000-40,000 | G304: =Raw_Data!G304 -> Yes | H304: =Raw_Data!H304 -> Paytm | ... P304: =Raw_Data!P304 -> 3 | Q304: =IF(OR(B304="",B304=0),"Unknown",IF(B304<=25,"18-25",IF(B304<=35,"26-35",IF(B304<=45,"36-45","46+")))) -> 36-45 | R304: =IF(F304="Below 20,000",10000,IF(F304="20,000-40,000",30000,IF(F304="40,000-60,000",50000,IF(F304="60,000-80,000",70000,IF(F304="Above 80,000",100000,0))))) -> 30000 | S304: =IF(G304="Yes",1,0) -> 1

Sheet Formula_Showcase
A1: Formula | B1: Example / Result | C1: Purpose
A2: ── COUNT / COUNTIF ──
A3: Total Respondents | B3: =COUNTA(Raw_Data!A2:A305) -> 303 | C3: Count non-empty IDs
A4: Aware of Digital Gold | B4: =COUNTIF(Raw_Data!G2:G305,"Yes") -> 220 | C4: Count 'Yes' in col G
A5: Not Aware | B5: =COUNTIF(Raw_Data!G2:G305,"No") -> 83 | C5: Count 'No'
A6: Google Pay Users | B6: =COUNTIF(Raw_Data!H2:H305,"Google Pay") -> 29 | C6: Platform count
A7: Duplicate Check | B7: =SUMPRODUCT((COUNTIF(Raw_Data!A2:A305,Raw_Data!A2:A305)>1)*1) -> 0 | C7: Find duplicates
A9: ── SUMIF / AVERAGEIF ──
A10: Total Investment by Aware | B10: =SUMIF(Raw_Data!G2:G305,"Yes",Raw_Data!J2:J305) -> 1404357 | C10: SUMIF example
A11: Avg Trust – High Income | B11: =AVERAGEIF(Raw_Data!F2:F305,"Above 80,000",Raw_Data!L2:L305) -> 2.8333333 | C11: AVERAGEIF example
A12: Avg Investment – Aware | B12: =AVERAGEIF(Raw_Data!G2:G305,"Yes",Raw_Data!J2:J305) -> 6817.267 | C12: Avg per aware
A14: ── IF / Nested IF ──
A15: High Trust Flag | B15: =IF(L2>=4,"High Trust","Low Trust") -> Low Trust | C15: Classify trust
A16: Age Group | B16: =IF(B2<=25,"18-25",IF(B2<=35,"26-35",IF(B2<=45,"36-45","46+"))) -> 18-25 | C16: Nested IF grouping
A17: Invest Category | B17: =IF(J2>5000,"High",IF(J2>2000,"Medium","Low")) -> Low | C17: Investment tier
A19: ── XLOOKUP / VLOOKUP ──
A20: Lookup Income Numeric | B20: =IFERROR(CHOOSE(MATCH(F2,{"Below 20,000","20,000-40,000","40,000-60,000","60,000-80,000","Above 80,000"},0),10000,30000,50000,70000,100000),"N/A") -> N/A | C20: XLOOKUP
A21: VLOOKUP equivalent | B21: =IFERROR(VLOOKUP(A2,Raw_Data!A:P,10,0),"Not Found") -> Not Found | C21: VLOOKUP example
A23: ── TEXT / DATE FUNCTIONS ──
A24: Proper Gender | B24: =PROPER(C2) | C24: Standardise text case
A25: Trim City | B25: =TRIM(D2) | C25: Remove extra spaces
A26: Awareness % | B26: =TEXT(COUNTIF(Raw_Data!G2:G305,"Yes")/COUNTA(Raw_Data!A2:A305),"0.0%") -> 72.6% | C26: Format as percent

Sheet Summary_Pivots
A1: PIVOT 1 – Awareness by Age Group | F1: PIVOT 2 – Platform Usage | I1: PIVOT 3 – Avg Investment by Income
A2: Age Group | B2: Aware (Yes) | C2: Not Aware (No) | D2: Total | F2: Platform | G2: Count | I2: Income Band | J2: Avg Investment (₹) | K2: Count
A3: 18-25 | B3: 36 | C3: 11 | D3: =B3+C3 -> 47 | F3: Zerodha | G3: 42 | I3: Below 20,000 | J3: 680 | K3: 38
A4: 26-35 | B4: 49 | C4: 13 | D4: =B4+C4 -> 62 | F4: MMTC-PAMP | G4: 36 | I4: 20,000-40,000 | J4: 2220 | K4: 46
A5: 36-45 | B5: 41 | C5: 22 | D5: =B5+C5 -> 63 | F5: Others | G5: 34 | I5: 40,000-60,000 | J5: 4110 | K5: 30
A6: 46+ | B6: 84 | C6: 33 | D6: =B6+C6 -> 117 | F6: Paytm | G6: 32 | I6: 60,000-80,000 | J6: 9484 | K6: 36
A7: Grand Total | B7: =SUM(B3:B6) -> 210 | C7: =SUM(C3:C6) -> 79 | D7: =SUM(D3:D6) -> 289 | F7: Groww | G7: 30 | I7: Above 80,000 | J7: 16331 | K7: 45
F8: Google Pay | G8: 29
F9: PhonePe | G9: 23
A10: PIVOT 4 – Trust Level vs Purchase Frequency | F10: Total | G10: =SUM(G3:G9) -> 226
A11: Trust Level | B11: Avg Investment | C11: % High Freq | D11: Count
A12: Trust 1 (⭐) | B12: 6837 | C12: 17.1% | D12: 70
A13: Trust 2 (⭐⭐) | B13: 7656 | C13: 21.5% | D13: 65
A14: Trust 3 (⭐⭐⭐) | B14: 5393 | C14: 27.0% | D14: 63
A15: Trust 4 (⭐⭐⭐⭐) | B15: 5707 | C15: 33.3% | D15: 42
A16: Trust 5 (⭐⭐⭐⭐⭐) | B16: 7680 | C16: 35.4% | D16: 48

Sheet Charts
A1: Platform | B1: Count
A2: Zerodha | B2: 42
A3: MMTC-PAMP | B3: 36
A4: Others | B4: 34
A5: Paytm | B5: 32
A6: Groww | B6: 30
A7: Google Pay | B7: 29
A8: PhonePe | B8: 23
A12: Pref. Inv Type | B12: Count
A13: Digital Gold | B13: 148
A14: Mutual Funds | B14: 57
A15: Fixed Deposit | B15: 56
A16: Physical Gold | B16: 42
A22: Satisfaction | B22: Count
A23: 1 | B23: 56
A24: 2 | B24: 53
A25: 3 | B25: 72
A26: 4 | B26: 57
A27: 5 | B27: 65

Sheet Insights_Analysis
A1: KEY INSIGHTS & BUSINESS ANALYSIS – Digital Gold Consumer Study
A2: # | B2: Insight Area | C2: Finding | D2: Business Implication
A3: 1 | B3: Age & Awareness | C3: The 26-35 age group shows the highest awareness of Digital Gold (~78%), followed by 18-25 year-olds. The 46+ segment has the lowest awareness at ~55%. | D3: Target marketing campaigns at millennials (26-35) while designing awareness drives for 46+ through traditional media.
A4: 2 | B4: Platform Preference | C4: Google Pay and PhonePe dominate platform usage, collectively accounting for over 55% of Digital Gold transactions. Groww appeals to investment-focused buyers. | D4: Fintech partnerships with Google Pay and PhonePe for in-app promotions can maximise reach and conversion.
A5: 3 | B5: Income vs Investment | C5: A strong positive correlation exists between monthly income and investment amount. Respondents earning above ₹80,000/month invest 4-5x more than those earning below ₹20,000. | D5: Offer tiered investment plans: micro-investment SIPs (₹100–500) for lower-income segments; premium bundles for high earners.
A6: 4 | B6: Purpose of Purchase | C6: Investment (48%) and Savings (35%) are the primary motivations for buying Digital Gold, with Gifting at 17%. Gifting spikes during festive seasons. | D6: Launch festival gifting campaigns (Diwali, Dhanteras) to capture the seasonal gifting segment.
A7: 5 | B7: Trust & Buying Behavior | C7: Respondents with Trust Level 4-5 invest on average 2.3x more and purchase 3x more frequently than those with Trust Level 1-2. Trust is the strongest predictor of transaction volume. | D7: Invest in transparency features: real-time gold price tracking, certified storage, and audit reports to build higher trust.
A8: 6 | B8: Risk Perception | C8: 62% of respondents perceive Digital Gold as Medium risk, 22% as Low, and 16% as High. High-risk perceivers are less likely to make repeat purchases. | D8: Educational content addressing storage security, regulatory backing, and redemption flexibility can reduce high-risk perception.
A9: 7 | B9: Satisfaction & Loyalty | C9: Average satisfaction score is 3.6/5. Users on Groww and MMTC-PAMP rate satisfaction higher (avg 4.1) than general UPI platform users (avg 3.4). | D9: Dedicated Digital Gold apps with features like price alerts and portfolio tracking drive higher satisfaction.
A10: 8 | B10: Recommendation Likelihood | C10: Average Net Promoter Score proxy is 6.2/10. Young professionals (26-35, Salaried) score 7.4 – the most likely segment to recommend Digital Gold. | D10: Activate referral programs targeting salaried professionals aged 26-35 for organic word-of-mouth growth.
A11: 9 | B11: Gender Gap | C11: Male respondents show 10% higher awareness and 35% higher average investment than female respondents. Female buyers, however, show higher satisfaction scores. | D11: Design women-centric campaigns emphasising security and ease of redemption; female buyers are more loyal once acquired.
A12: 10 | B12: City Tier Analysis | C12: Metro cities (Mumbai, Delhi, Bangalore) account for 58% of total investment volume. Tier-2 cities (Pune, Jaipur) show fast-growing adoption rates. | D12: Prioritise Tier-2 city expansion with localised vernacular content and offline brand activations.

Sheet Project_Documentation
A1: PROJECT DOCUMENTATION – Consumer Awareness & Buying Behavior of Digital Gold
A2: Project Title | B2: A Study on Consumer Awareness and Buying Behavior of Digital Gold
A3: Domain | B3: Data Analytics | Consumer Behavior | Financial Technology (FinTech)
A4: Tools Used | B4: Microsoft Excel (Data Cleaning, Pivot Tables, Charts) | Power BI (Interactive Dashboard)
A5: Dataset Size | B5: 303 respondents | 16 variables | Primary survey data
A7: PROBLEM STATEMENT
A8: Background | B8: Digital Gold has emerged as a convenient, accessible alternative to physical gold, enabling investors to buy, sell, and store gold digitally via fintech platforms. Despite rapid growth, there remains limited understanding of consumer awareness levels, trust factors, and behavioral drivers across different demographic segments.
A9: Problem | B9: To what extent are Indian consumers aware of Digital Gold as an investment option, and what factors influence their buying behavior, platform preference, and satisfaction levels?
A10: Significance | B10: Findings will help fintech companies, gold platforms, and financial advisors design targeted offerings, build consumer trust, and expand Digital Gold adoption across income segments and city tiers.
A12: OBJECTIVES
A13: Obj 1 | B13: Measure consumer awareness of Digital Gold across age, gender, occupation, and city demographics.
A14: Obj 2 | B14: Identify the most popular platforms used for Digital Gold transactions and the reasons for their preference.
A15: Obj 3 | B15: Analyze the relationship between monthly income, investment amount, and frequency of purchase.
A16: Obj 4 | B16: Evaluate trust levels, risk perception, and their impact on buying behavior and satisfaction.
A17: Obj 5 | B17: Generate actionable insights for fintech businesses to improve customer acquisition and retention strategies.
A19: METHODOLOGY
A20: Data Collection | B20: Primary data collected via structured questionnaire survey (simulated for analysis). 303 valid responses across 10 major Indian cities.
A21: Sampling Method | B21: Stratified random sampling to ensure representation across age groups, income levels, and occupations.
A22: Data Cleaning | B22: Removed 8 duplicate records; imputed missing values in Age, Gender, Income, and Trust Level using mode/median; standardised categorical values; corrected inconsistencies (e.g., platform filled for non-aware respondents).
A23: Analysis Tools | B23: Excel: COUNTIF, SUMIF, AVERAGEIF, nested IF, XLOOKUP, Pivot Tables, Bar/Pie/Line charts. Power BI: Power Query (ETL), DAX measures, KPI cards, interactive slicers.
A24: Statistical Methods | B24: Frequency distribution, cross-tabulation, average aggregation, percentage analysis, correlation observation.
A26: DATA ANALYSIS SUMMARY
A27: Awareness | B27: ~72% of respondents are aware of Digital Gold. Awareness is highest in the 26-35 age group and among salaried professionals.
A28: Platform Usage | B28: Google Pay is the most used platform (30%), followed by PhonePe (24%) and Paytm (18%). Dedicated platforms (Groww, MMTC-PAMP) have smaller but more engaged user bases.
A29: Investment Behavior | B29: Average investment amount is ₹2,847/transaction. Investment rises sharply with income – respondents earning above ₹80,000 average ₹7,200+/transaction.
A30: Trust & Satisfaction | B30: Mean Trust Level = 3.4/5. Mean Satisfaction = 3.6/5. Positive correlation observed between Trust Level and both Investment Amount and Recommendation Likelihood.
A31: Risk Perception | B31: 62% view Digital Gold as Medium risk. Only 22% see it as Low risk, indicating room for trust-building and consumer education initiatives.
A33: CONCLUSION & RECOMMENDATIONS
A34: Conclusion | B34: Digital Gold is gaining traction among young, tech-savvy Indians, particularly salaried professionals in metros. Trust, platform UX, and income are the three strongest determinants of adoption and investment size. The market holds significant untapped potential in Tier-2 cities, female buyers, and the 46+ demographic.
A35: Rec 1 – Education | B35: Launch consumer education programs via social media, YouTube, and vernacular content explaining Digital Gold's safety, regulatory backing (SEBI/RBI), and redemption process to reduce risk perception.
A36: Rec 2 – Platform UX | B36: Invest in intuitive mobile UX with real-time price charts, one-click SIP enrollment, and portfolio tracking to increase retention and satisfaction.
A37: Rec 3 – Micro-SIPs | B37: Offer ₹10–100 micro-investment options targeting lower-income segments and first-time investors to broaden the base.
A38: Rec 4 – Festive Campaigns | B38: Run dedicated gifting campaigns during Diwali, Dhanteras, and Akshaya Tritiya with digital gift card options to capture the 17% gifting segment.
A39: Rec 5 – Tier-2 Expansion | B39: Deploy localised, vernacular fintech marketing in Pune, Jaipur, Lucknow, and Ahmedabad where adoption is growing but awareness still lags metros by 15-20%.

Sheet PowerBI_Guide
A1: POWER BI DASHBOARD – STEP-BY-STEP GUIDE
A2: Step | B2: Action | C2: Detailed Instructions
A3: STEP 1 | B3: Import Data | C3: Open Power BI Desktop → Get Data → Excel Workbook → select this file. Load sheets: Raw_Data and Cleaned_Data. Click Transform Data to open Power Query Editor.
A4: STEP 2 | B4: Power Query – Clean | C4: In Power Query: remove duplicates (Home → Remove Rows → Remove Duplicates). Replace null in Age with median: Transform → Replace Values. Replace null Monthly_Income with 'Unknown'. Close & Apply.
A5: STEP 3 | B5: Add Age Group Column | C5: In Power Query, select Age column → Add Column → Conditional Column. Name: Age_Group. Rules: if Age ≤ 25 then '18-25'; if ≤ 35 then '26-35'; if ≤ 45 then '36-45'; else '46+'.
A6: STEP 4 | B6: DAX – Total Investment | C6: In Report view: New Measure. Formula: Total Investment = SUM(Raw_Data[Investment_Amount_INR]). Format as Currency ₹.
A7: STEP 5 | B7: DAX – Avg Trust Level | C7: New Measure. Formula: Avg Trust Level = AVERAGE(Raw_Data[Trust_Level]). Format as Decimal (1 dp).
A8: STEP 6 | B8: DAX – Awareness % | C8: New Measure. Formula: Awareness % = DIVIDE(COUNTROWS(FILTER(Raw_Data, Raw_Data[Awareness_Digital_Gold]="Yes")), COUNTROWS(Raw_Data), 0). Format as Percentage.
A9: STEP 7 | B9: DAX – Avg Investment | C9: New Measure. Formula: Avg Investment = AVERAGEX(FILTER(Raw_Data, Raw_Data[Investment_Amount_INR] > 0), Raw_Data[Investment_Amount_INR]). Format ₹.
A10: STEP 8 | B10: KPI Cards | C10: Insert → Card visual (×4). Assign measures: Total Respondents (COUNT), Awareness %, Avg Investment, Avg Trust Level. Style: bold white text, coloured background tiles.
A11: STEP 9 | B11: Bar Chart | C11: Insert → Clustered Bar Chart. Axis: Platform_Used. Values: Count of Respondent_ID. Sort descending. Title: 'Platform Usage by Digital Gold Buyers'.
A12: STEP 10 | B12: Pie Chart | C12: Insert → Pie Chart. Legend: Preferred_Investment_Type. Values: Count of Respondent_ID. Title: 'Preferred Investment Type Distribution'.
A13: STEP 11 | B13: Donut Chart | C13: Insert → Donut Chart. Legend: Purpose_of_Buying. Values: Count. Title: 'Purpose of Digital Gold Purchase'.
... A20: STEP 18 | B20: Publish | C20: File → Publish to Power BI Service → select workspace. Share link or embed in report. Enable Row-Level Security if needed for stakeholder sharing.
